Workbook

Sheet Penetration
A1: Technology penetration - share of NEW VEHICLES SOLD
A2: One row per Driver x Segment x State x Year. Shares of a driver sum to 1 within a segment-year (see Checks). Add or delete rows freely - the model fits a smooth monotone curve through whatever anchor years are present.
A3: YELLOW = editable. ORANGE source text = my assumption, please correct. This file supersedes 16_BEV_wiring_transition_parameters.xlsx.
A5: Driver | B5: Segment | C5: State | D5: Year | E5: Share_Min | F5: Share_Mode | G5: Share_Max | H5: Source
A6: Architecture | B6: EF | C6: Conventional | D6: 2010 | E6: 0.73404224 | F6: 0.85404224 | G6: 0.97404224 | H6: DERIVED from agreed timing; Conventional->Transitional timing is my proposal - CORRECT ME
A7: Architecture | B7: EF | C7: Transitional | D7: 2010 | E7: 0.025322663 | F7: 0.14532266 | G7: 0.26532266 | H7: DERIVED from agreed timing; Conventional->Transitional timing is my proposal - CORRECT ME
A8: Architecture | B8: EF | C8: SDV_Zonal | D8: 2010 | E8: 0 | F8: 0.00063509704 | G8: 0.1206351 | H8: DERIVED from agreed timing; Conventional->Transitional timing is my proposal - CORRECT ME
A9: Architecture | B9: EF | C9: Conventional | D9: 2015 | E9: 0.45308372 | F9: 0.57308372 | G9: 0.69308372 | H9: DERIVED from agreed timing; Conventional->Transitional timing is my proposal - CORRECT ME
A10: Architecture | B10: EF | C10: Transitional | D10: 2015 | E10: 0.30292968 | F10: 0.42292968 | G10: 0.54292968 | H10: DERIVED from agreed timing; Conventional->Transitional timing is my proposal - CORRECT ME
A11: Architecture | B11: EF | C11: SDV_Zonal | D11: 2015 | E11: 0 | F11: 0.0039865956 | G11: 0.1239866 | H11: DERIVED from agreed timing; Conventional->Transitional timing is my proposal - CORRECT ME
A12: Architecture | B12: EF | C12: Conventional | D12: 2020 | E12: 0.11545239 | F12: 0.23545239 | G12: 0.35545239 | H12: DERIVED from agreed timing; Conventional->Transitional timing is my proposal - CORRECT ME
A13: Architecture | B13: EF | C13: Transitional | D13: 2020 | E13: 0.61995835 | F13: 0.73995835 | G13: 0.85995835 | H13: DERIVED from agreed timing; Conventional->Transitional timing is my proposal - CORRECT ME
A14: Architecture | B14: EF | C14: SDV_Zonal | D14: 2020 | E14: 0 | F14: 0.024589264 | G14: 0.14458926 | H14: DERIVED from agreed timing; Conventional->Transitional timing is my proposal - CORRECT ME
A15: Architecture | B15: EF | C15: Conventional | D15: 2025 | E15: 0 | F15: 0.065989313 | G15: 0.18598931 | H15: DERIVED from agreed timing; Conventional->Transitional timing is my proposal - CORRECT ME
A16: Architecture | B16: EF | C16: Transitional | D16: 2025 | E16: 0.67699184 | F16: 0.79699184 | G16: 0.91699184 | H16: DERIVED from agreed timing; Conventional->Transitional timing is my proposal - CORRECT ME
A17: Architecture | B17: EF | C17: SDV_Zonal | D17: 2025 | E17: 0.017018847 | F17: 0.13701885 | G17: 0.25701885 | H17: DERIVED from agreed timing; Conventional->Transitional timing is my proposal - CORRECT ME
... A368: Autonomy | B368: AB | C368: L5 | D368: 2070 | E368: 0.83 | F368: 0.95 | G368: 1 | H368: MY GUESS - AB/CD reasoning: EU GSR (2019/2144) mandates AEB + lane keep + ISA on ALL new registrations from Jul 2024, so L0 cannot persist. AB lags CD by ~5-10y, CD lags EF by ~5y.

Sheet Sensors_per_Level
A1: Sensor complement per autonomy level - the shared input for BOTH models
A2: This is what 06_VehicleSensorNumbers.xlsx lacks: a level dimension. The wiring model turns these counts into ADAS/sensor wire length; the sensor model should read the SAME table so the two cannot drift apart.
A3: ALL VALUES BELOW ARE MY ASSUMPTION (orange). Nothing here comes from a source - please overwrite.
A5: Level | B5: Sensor_Type | C5: Count_Min | D5: Count_Mode | E5: Count_Max | F5: Note
A6: L0 | B6: camera | C6: 0 | D6: 1 | E6: 1 | F6: reversing camera only
A7: L0 | B7: radar | C7: 0 | D7: 0 | E7: 1
A8: L0 | B8: lidar | C8: 0 | D8: 0 | E8: 0
A9: L0 | B9: ultrasonic | C9: 0 | D9: 4 | E9: 8 | F9: park assist
A10: L1 | B10: camera | C10: 1 | D10: 1 | E10: 2 | F10: EU GSR: AEB + lane keep + sign recognition
A11: L1 | B11: radar | C11: 1 | D11: 1 | E11: 2 | F11: front radar for AEB/ACC
A12: L1 | B12: lidar | C12: 0 | D12: 0 | E12: 0
A13: L1 | B13: ultrasonic | C13: 4 | D13: 8 | E13: 10
A14: L2 | B14: camera | C14: 2 | D14: 3 | E14: 5 | F14: front + surround; sign reading, lane centring
A15: L2 | B15: radar | C15: 3 | D15: 4 | E15: 5 | F15: front + corner
A16: L2 | B16: lidar | C16: 0 | D16: 0 | E16: 1
A17: L2 | B17: ultrasonic | C17: 8 | D17: 10 | E17: 12
A18: L3 | B18: camera | C18: 6 | D18: 7 | E18: 9 | F18: eyes-off in ODD, redundancy required
A19: L3 | B19: radar | C19: 5 | D19: 6 | E19: 8
A20: L3 | B20: lidar | C20: 1 | D20: 1 | E20: 2
A21: L3 | B21: ultrasonic | C21: 10 | D21: 12 | E21: 12
A22: L4 | B22: camera | C22: 8 | D22: 11 | E22: 14 | F22: no driver in ODD, full redundancy
A23: L4 | B23: radar | C23: 6 | D23: 8 | E23: 10
A24: L4 | B24: lidar | C24: 2 | D24: 3 | E24: 4
A25: L4 | B25: ultrasonic | C25: 10 | D25: 12 | E25: 14
A26: L5 | B26: camera | C26: 12 | D26: 14 | E26: 18 | F26: no ODD limit
A27: L5 | B27: radar | C27: 8 | D27: 10 | E27: 12
A28: L5 | B28: lidar | C28: 4 | D28: 5 | E28: 7
A29: L5 | B29: ultrasonic | C29: 10 | D29: 12 | E29: 16

Sheet Metres_per_Sensor
A1: Wire length per sensor - links sensor counts to harness length
A2: Camera and ultrasonic are DERIVED and cross-validated: 17_ ADAS length / 06_ sensor count gives 28 / 25 / 31 m per camera and 1.8 / 0.9 / 1.7 m per ultrasonic for AB / CD / EF. Two independently built datasets agreeing is a real check, not a fit.
A3: Radar and lidar revised 2026-08-04 using YOUR placement information. They still cannot be derived - 06_ has no radar or lidar rows - but the values are now grounded in where the sensor physically sits.
A5: Sensor_Type | B5: Segment | C5: m_Min | D5: m_Mode | E5: m_Max | F5: Basis | G5: Placement (your input)
A6: camera | B6: AB | C6: 22 | D6: 28 | E6: 36 | F6: DERIVED 17_/06_ | G6: front, rear, both mirrors - distributed, so a long average run
A7: camera | B7: CD | C7: 20 | D7: 25 | E7: 32 | F7: DERIVED 17_/06_ | G7: as above
A8: camera | B8: EF | C8: 24 | D8: 31 | E8: 40 | F8: DERIVED 17_/06_ | G8: as above
A9: ultrasonic | B9: AB | C9: 1 | D9: 1.8 | E9: 2.6 | F9: DERIVED 17_/06_ | G9: bumper-local, very short runs
A10: ultrasonic | B10: CD | C10: 0.6 | D10: 0.9 | E10: 1.4 | F10: DERIVED 17_/06_ | G10: as above
A11: ultrasonic | B11: EF | C11: 1 | D11: 1.7 | E11: 2.4 | F11: DERIVED 17_/06_ | G11: as above
A12: radar | B12: AB | C12: 6 | D12: 10 | E12: 16 | F12: 17_ ADAS_RADAR 10 m / ~1 radar in AB | G12: FRONT and FRONT-SIDE only - all at one end, so shorter than a camera average
A13: radar | B13: CD | C13: 6 | D13: 10 | E13: 16 | F13: ASSUMPTION - see conflict note | G13: front + front corners
A14: radar | B14: EF | C14: 7 | D14: 12 | E14: 18 | F14: ASSUMPTION | G14: front + front corners
A15: lidar | B15: AB | C15: 7 | D15: 12 | E15: 20 | F15: ASSUMPTION | G15: ROOF mainly (short drop to compute), some REAR and SIDE (full-length runs)
A16: lidar | B16: CD | C16: 8 | D16: 14 | E16: 22 | F16: ASSUMPTION | G16: roof + rear + side mix
A17: lidar | B17: EF | C17: 10 | D17: 18 | E17: 28 | F17: ASSUMPTION | G17: roof + rear + side mix, longest vehicle
A20: CONFLICT | B20: 17_ gives ADAS_RADAR totals of 10 / 12 / 18 m for AB / CD / EF. With ~1 radar in AB that is 10 m per radar, but CD at L2 has ~4 radars, which would give only 3 m each. The two cannot both be right - the CD/EF radar totals in 17_ look too low for their sensor count. Radar mode is set to ~10 m on the AB reading; widen the band if you disagree.

Sheet Checks
A1: Do the shares sum to 1?
A2: Any row not showing 1.00 needs fixing before the model is run. Formulas read the Penetration sheet live.
A4: Driver | B4: Segment | C4: Year | D4: Sum of Share_Mode
A5: Architecture | B5: AB | C5: 2010 | D5: =SUMIFS(Penetration!$F$6:$F$368,Penetration!$A$6:$A$368,$A5,Penetration!$B$6:$B$368,$B5,Penetration!$D$6:$D$368,$C5)
A6: Architecture | B6: AB | C6: 2015 | D6: =SUMIFS(Penetration!$F$6:$F$368,Penetration!$A$6:$A$368,$A6,Penetration!$B$6:$B$368,$B6,Penetration!$D$6:$D$368,$C6)
A7: Architecture | B7: AB | C7: 2020 | D7: =SUMIFS(Penetration!$F$6:$F$368,Penetration!$A$6:$A$368,$A7,Penetration!$B$6:$B$368,$B7,Penetration!$D$6:$D$368,$C7)
A8: Architecture | B8: AB | C8: 2025 | D8: =SUMIFS(Penetration!$F$6:$F$368,Penetration!$A$6:$A$368,$A8,Penetration!$B$6:$B$368,$B8,Penetration!$D$6:$D$368,$C8)
A9: Architecture | B9: AB | C9: 2030 | D9: =SUMIFS(Penetration!$F$6:$F$368,Penetration!$A$6:$A$368,$A9,Penetration!$B$6:$B$368,$B9,Penetration!$D$6:$D$368,$C9)
A10: Architecture | B10: AB | C10: 2035 | D10: =SUMIFS(Penetration!$F$6:$F$368,Penetration!$A$6:$A$368,$A10,Penetration!$B$6:$B$368,$B10,Penetration!$D$6:$D$368,$C10)
A11: Architecture | B11: AB | C11: 2040 | D11: =SUMIFS(Penetration!$F$6:$F$368,Penetration!$A$6:$A$368,$A11,Penetration!$B$6:$B$368,$B11,Penetration!$D$6:$D$368,$C11)
A12: Architecture | B12: AB | C12: 2045 | D12: =SUMIFS(Penetration!$F$6:$F$368,Penetration!$A$6:$A$368,$A12,Penetration!$B$6:$B$368,$B12,Penetration!$D$6:$D$368,$C12)
A13: Architecture | B13: AB | C13: 2050 | D13: =SUMIFS(Penetration!$F$6:$F$368,Penetration!$A$6:$A$368,$A13,Penetration!$B$6:$B$368,$B13,Penetration!$D$6:$D$368,$C13)
A14: Architecture | B14: AB | C14: 2060 | D14: =SUMIFS(Penetration!$F$6:$F$368,Penetration!$A$6:$A$368,$A14,Penetration!$B$6:$B$368,$B14,Penetration!$D$6:$D$368,$C14)
A15: Architecture | B15: AB | C15: 2070 | D15: =SUMIFS(Penetration!$F$6:$F$368,Penetration!$A$6:$A$368,$A15,Penetration!$B$6:$B$368,$B15,Penetration!$D$6:$D$368,$C15)
A16: Architecture | B16: CD | C16: 2010 | D16: =SUMIFS(Penetration!$F$6:$F$368,Penetration!$A$6:$A$368,$A16,Penetration!$B$6:$B$368,$B16,Penetration!$D$6:$D$368,$C16)
... A103: Autonomy | B103: EF | C103: 2070 | D103: =SUMIFS(Penetration!$F$6:$F$368,Penetration!$A$6:$A$368,$A103,Penetration!$B$6:$B$368,$B103,Penetration!$D$6:$D$368,$C103)

Sheet Notes
A1: What is yours, what is mine, and what is still missing
A3: FROM YOU | B3: EF already L3 in 2025; L4 ~20% by 2030; L5 ~20% by 2035; full adoption 2040-45.
A4: FROM YOU | B4: CD already reads signs and some lane following, but not full street driving -> treated as L2 dominant.
A5: FROM YOU | B5: AB has not started, except EU-mandated features such as collision avoidance -> treated as L0/L1.
A6: FROM YOU | B6: Transitions mean old designs persist while new ones phase in, which should WIDEN uncertainty.
A7: FROM YOU | B7: BEV entry ~2010; do not model earlier.
A8: FROM YOU | B8: New architecture shortens wiring, but new sensors lengthen it. Both must act independently.
A10: MY GUESS | B10: Everything on Sensors_per_Level. No source. Most consequential sheet in the file - please review first.
A11: MY GUESS | B11: Radar and lidar metres-per-sensor. CORRECTED 2026-08-05: 06_ DOES have radar and lidar rows (components Front long-range radar, Corner short/mid-range radars, LiDAR sensor); their SensorType values are the physical parts (RF transceiver, laser diode array, photodetector array), not the words radar/lidar. Its EF radar (5) and lidar (0-1) counts match the measured EQS, i7 and EX90 exactly. The METRES-PER-SENSOR figures remain assumptions - that part of this note stands.
A12: MY GUESS | B12: CD and AB autonomy shares away from the years you specified.
A13: MY GUESS | B13: Conventional->Transitional architecture timing (EF 2016/2026, CD 2018/2029, AB 2020/2032).
A14: MY GUESS | B14: The +/-0.12 share band on every derived row. Widen where you are less sure.
A16: GAP | B16: CORRECTED 2026-08-05: the claim that 06_ has NO radar and NO lidar rows was WRONG - it was a naming mismatch, not missing data (see row 11). The real gap is that 06_ has no TIME and no TIER dimension, and that its camera counts are low (EF max 5 vs 6-10 measured). See Data/Sources/ADAS_Sensor_Adoption_Report_2025_2070.md section 2.3.
... A20: MECHANISM | B20: Architecture state is drawn DISCRETELY per iteration, not share-weighted: a vehicle is either an old
B21: design or a new one. Uncertainty then peaks mid-transition (band ~188% of median vs ~71% once settled),
B22: which is the behaviour you described. Share-weighting averaged it away.
A24: SUPERSEDED | B24: 2026-08-05: sheet Sensors_per_Level is NO LONGER READ by Wiring/BevWiring.py. It was keyed on SAE CERTIFICATION level; the model now uses an installed-HARDWARE-TIER axis in Data/19_ADAS_sensor_adoption.xlsx (drivers A/B/C). Sheet Metres_per_Sensor IS still read, unchanged. Set USE_TIER_AXIS=False in BevWiring.py section 0 to restore the old path for comparison. Rationale: Wiring/AUTONOMY_LEVELS_VS_HARDWARE.md.

Sheet Report_Scenarios
A1: SOURCE: your BEV_Automation_Adoption_Report_2020_2050.md, Section 6
A2: % of GLOBAL IN-USE BEV FLEET by maximum SAE capability. Each row sums to 100.
A3: WARNING: the report calls these scenarios AB / CD / EF. Those are NOT vehicle size segments. Renamed here to avoid the collision.
A5: Conservative (report calls this 'AB')
A6: Year | B6: L0 | C6: L1 | D6: L2 | E6: L3 | F6: L4 | G6: L5
A7: 2020 | B7: 0.35 | C7: 0.1 | D7: 0.53 | E7: 0.02 | F7: 0 | G7: 0
A8: 2025 | B8: 0.2 | C8: 0.08 | D8: 0.64 | E8: 0.07 | F8: 0.01 | G8: 0
A9: 2030 | B9: 0.1 | C9: 0.05 | D9: 0.7 | E9: 0.12 | F9: 0.03 | G9: 0
A10: 2035 | B10: 0.07 | C10: 0.04 | D10: 0.68 | E10: 0.16 | F10: 0.05 | G10: 0
A11: 2040 | B11: 0.05 | C11: 0.03 | D11: 0.64 | E11: 0.2 | F11: 0.07 | G11: 0.01
A12: 2045 | B12: 0.04 | C12: 0.02 | D12: 0.59 | E12: 0.24 | F12: 0.1 | G12: 0.01
A13: 2050 | B13: 0.03 | C13: 0.02 | D13: 0.54 | E13: 0.27 | F13: 0.12 | G13: 0.02
A16: Central (report calls this 'CD')
A17: Year | B17: L0 | C17: L1 | D17: L2 | E17: L3 | F17: L4 | G17: L5
A18: 2020 | B18: 0.35 | C18: 0.1 | D18: 0.53 | E18: 0.02 | F18: 0 | G18: 0
A19: 2025 | B19: 0.18 | C19: 0.07 | D19: 0.65 | E19: 0.08 | F19: 0.02 | G19: 0
A20: 2030 | B20: 0.08 | C20: 0.04 | D20: 0.69 | E20: 0.14 | F20: 0.05 | G20: 0
A21: 2035 | B21: 0.05 | C21: 0.03 | D21: 0.63 | E21: 0.19 | F21: 0.09 | G21: 0.01
A22: 2040 | B22: 0.03 | C22: 0.02 | D22: 0.55 | E22: 0.22 | F22: 0.16 | G22: 0.02
A23: 2045 | B23: 0.02 | C23: 0.01 | D23: 0.47 | E23: 0.23 | F23: 0.24 | G23: 0.03
A24: 2050 | B24: 0.01 | C24: 0.01 | D24: 0.39 | E24: 0.23 | F24: 0.31 | G24: 0.05
A27: Accelerated (report calls this 'EF')
A28: Year | B28: L0 | C28: L1 | D28: L2 | E28: L3 | F28: L4 | G28: L5
A29: 2020 | B29: 0.35 | C29: 0.1 | D29: 0.53 | E29: 0.02 | F29: 0 | G29: 0
A30: 2025 | B30: 0.16 | C30: 0.06 | D30: 0.66 | E30: 0.09 | F30: 0.03 | G30: 0
A31: 2030 | B31: 0.06 | C31: 0.03 | D31: 0.68 | E31: 0.16 | F31: 0.07 | G31: 0
A32: 2035 | B32: 0.03 | C32: 0.02 | D32: 0.59 | E32: 0.2 | F32: 0.14 | G32: 0.02
A33: 2040 | B33: 0.02 | C33: 0.01 | D33: 0.47 | E33: 0.2 | F33: 0.25 | G33: 0.05
A34: 2045 | B34: 0.01 | C34: 0.01 | D34: 0.36 | E34: 0.18 | F34: 0.36 | G34: 0.08
A35: 2050 | B35: 0.01 | C35: 0 | D35: 0.29 | E35: 0.15 | F35: 0.44 | G35: 0.11

Sheet Conversion
A1: Conversion: global in-use fleet -> European private NEW VEHICLES SOLD, by size segment
A2: Edit the yellow cells. Every number on Autonomy_Derived recalculates. This is where you generate different scenarios.
A4: Parameter | B4: Value | C4: Meaning
A5: Fleet_to_NewSales_lead_y | B5: 7 | C5: New sales LEAD the parc by roughly the mean fleet age. Positive = new sales are ahead. Raises the numbers.
A6: Private_lag_y | B6: 5 | C6: YOUR INPUT: private adoption follows robotaxi/commercial by ~5 years. Lowers the numbers.
A7: Europe_shift_y | B7: 0 | C7: Europe vs global. Goldman's only regional figure is 2040 (EU ~80%, US ~65%, CN ~90%) - roughly neutral.
A8: Offset_EF_y | B8: -5 | C8: EF leads the market average (premium first). Negative = earlier.
A9: Offset_CD_y | B9: 0 | C9: CD tracks the market average.
A10: Offset_AB_y | B10: 5 | C10: AB lags (cost sensitive).
A12: NET_SHIFT_EF | B12: =-$B$5+$B$6+$B$7+B8
A13: NET_SHIFT_CD | B13: =-$B$5+$B$6+$B$7+B9
A14: NET_SHIFT_AB | B14: =-$B$5+$B$6+$B$7+B10
A17: Scenario -> uncertainty band
A18: Share_Min | B18: Conservative | C18: Swap these to re-map which scenario drives which edge of the band.
A19: Share_Mode | B19: Central | C19: Swap these to re-map which scenario drives which edge of the band.
A20: Share_Max | B20: Accelerated | C20: Swap these to re-map which scenario drives which edge of the band.

Sheet Autonomy_Derived
A1: Autonomy shares - European private NEW VEHICLES SOLD, by size segment
A2: Every value is a FORMULA reading Report_Scenarios through the lags on Conversion. Change a lag and the whole sheet moves. Raw = straight conversion. Norm = rescaled so the six levels sum to 1. OVERRIDE (green) wins where you type a number.
A4: Segment | B4: Year | C4: Band | D4: Scenario used | E4: L0_raw | F4: L1_raw | G4: L2_raw | H4: L3_raw | I4: L4_raw | J4: L5_raw | K4: SUM_raw | L4: L0_norm | M4: L1_norm | N4: L2_norm | O4: L3_norm | P4: L4_norm | Q4: L5_norm | R4: L0_OVERRIDE | S4: L1_OVERRIDE | T4: L2_OVERRIDE | U4: L3_OVERRIDE | V4: L4_OVERRIDE | W4: L5_OVERRIDE
A5: AB | B5: 2020 | C5: Share_Min | D5: =Conversion!$B$18 | E5: =IF($D5="Conservative",IF(INDEX(Report_Scenarios!$A$7:$A$13,MIN(MATCH(MEDIAN($B5-Conversion!$B$16,2020,2050),Report_Scenarios!$A$7:$A$13,1)+1,7))=INDEX(Report_Scenarios!$A$7:$A$13,MATCH(MEDIAN($B5-Conversion!$B$16,2020,2050),Report_Scenarios!$A$7:$A$13,1)),INDEX(Report_Scenarios!$B$7:$B$13,MATCH(MEDIAN($B5-Conversion!$B$16,2020,2050),Report_Scenarios!$A$7:$A$13,1)),INDEX(Report_Scenarios!$B$7:$B$13,MATCH(MEDIAN($B5-Conversion!$B$16,2020,2050),Report_Scenarios!$A$7:$A$13,1))+(INDEX(Report_Scenarios!$B$7:$B$13,MIN(MATCH(MEDIAN($B5-Conversion!$B$16,2020,2050),Report_Scenarios!$A$7:$A$13,1)+1,7))-INDEX(Report_Scenarios!$B$7:$B$13,MATCH(MEDIAN($B5-Conversion!$B$16,2020,2050),Report_Scenarios!$A$7:$A$13,1)))*(MEDIAN($B5-Conversion!$B$16,2020,2050)-INDEX(Report_Scenarios!$A$7:$A$13,MATCH(MEDIAN($B5-Conversion!$B$16,2020,2050),Report_Scenarios!$A$7:$A$13,1)))/(INDEX(Report_Scenarios!$A$7:$A$13,MIN(MATCH(MEDIAN($B5-Conversion!$B$16,2020,2050),Report_Scenarios!$A$7:$A$13,1)+1,7))-INDEX(Report_Scenarios!$A$7:$A$13,MATCH(MEDIAN($B5-Conversion!$B$16,2020,2050),Report_Scenarios!$A$7:$A$13,1)))),IF($D5="Central",IF(INDEX(Report_Scenarios!$A$18:$A$24,MIN(MATCH(MEDIAN($B5-Conversion!$B$16,2020,2050),Report_Scenarios!$A$18:$A$24,1)+1,7))=INDEX(Report_Scenarios!$A$18:$A$24,MATCH(MEDIAN($B5-Conversion!$B$16,2020,2050),Report_Scenarios!$A$18:$A$24,1)),INDEX(Report_Scenarios!$B$18:$B$24,MATCH(MEDIAN($B5-Conversion!$B$16,2020,2050),Report_Scenarios!$A$18:$A$24,1)),INDEX(Report_Scenarios!$B$18:$B$24,MATCH(MEDIAN($B5-Conversion!$B$16,2020,2050),Report_Scenarios!$A$18:$A$24,1))+(INDEX(Report_Scenarios!$B$18:$B$24,MIN(MATCH(MEDIAN($B5-Conversion!$B$16,2020,2050),Report_Scenarios!$A$18:$A$24,1)+1,7))-INDEX(Report_Scenarios!$B$18:$B$24,MATCH(MEDIAN($B5-Conversion!$B$16,2020,2050),Report_Scenarios!$A$18:$A$24,1)))*(MEDIAN($B5-Conversion!$B$16,2020,2050)-INDEX(Report_Scenarios!$A$18:$A$24,MATCH(MEDIAN($B5-Conversion!$B$16,2020,2050),Report_Scenarios!$A$18:$A$24,1)))/(INDEX(Report_Scenarios!$A$18:$A$24,MIN(MATCH(MEDIAN($B5-Conversion!$B$16,2020,2050),Report_Scenarios!$A$18:$A$24,1)+1,7))-INDEX(Report_Scenarios!$A$18:$A$24,MATCH(MEDIAN($B5-Conversion!$B$16,2020,2050),Report_Scenarios!$A$18:$A$24,1)))),IF(INDEX(Report_Scenarios!$A$29:$A$35,MIN(MATCH(MEDIAN($B5-Conversion!$B$16,2020,2050),Report_Scenarios!$A$29:$A$35,1)+1,7))=INDEX(Report_Scenarios!$A$29:$A$35,MATCH(MEDIAN($B5-Conversion!$B$16,2020,2050),Report_Scenarios!$A$29:$A$35,1)),INDEX(Report_Scenarios!$B$29:$B$35,MATCH(MEDIAN($B5-Conversion!$B$16,2020,2050),Report_Scenarios!$A$29:$A$35,1)),INDEX(Report_Scenarios!$B$29:$B$35,MATCH(MEDIAN($B5-Conversion!$B$16,2020,2050),Report_Scenarios!$A$29:$A$35,1))+(INDEX(Report_Scenarios!$B$29:$B$35,MIN(MATCH(MEDIAN($B5-Conversion!$B$16,2020,2050),Report_Scenarios!$A$29:$A$35,1)+1,7))-INDEX(Report_Scenarios!$B$29:$B$35,MATCH(MEDIAN($B5-Conversion!$B$16,2020,2050),Report_Scenarios!$A$29:$A$35,1)))*(MEDIAN($B5-Conversion!$B$16,2020,2050)-INDEX(Report_Scenarios!$A$29:$A$35,MATCH(MEDIAN($B5-Conversion!$B$16,2020,2050),Report_Scenarios!$A$29:$A$35,1)))/(INDEX(Report_Scenarios!$A$29:$A$35,MIN(MATCH(MEDIAN($B5-Conversion!$B$16,2020,2050),Report_Scenarios!$A$29:$A$35,1)+1,7))-INDEX(Report_Scenarios!$A$29:$A$35,MATCH(MEDIAN($B5-Conversion!$B$16,2020,2050),Report_Scenarios!$A$29:$A$35,1)))))) | F5: =IF($D5="Conservative",IF(INDEX(Report_Scenarios!$A$7:$A$13,MIN(MATCH(MEDIAN($B5-Conversion!$B$16,2020,2050),Report_Scenarios!$A$7:$A$13,1)+1,7))=INDEX(Report_Scenarios!$A$7:$A$13,MATCH(MEDIAN($B5-Conversion!$B$16,2020,2050),Report_Scenarios!$A$7:$A$13,1)),INDEX(Report_Scenarios!$C$7:$C$13,MATCH(MEDIAN($B5-Conversion!$B$16,2020,2050),Report_Scenarios!$A$7:$A$13,1)),INDEX(Report_Scenarios!$C$7:$C$13,MATCH(MEDIAN($B5-Conversion!$B$16,2020,2050),Report_Scenarios!$A$7:$A$13,1))+(INDEX(Report_Scenarios!$C$7:$C$13,MIN(MATCH(MEDIAN($B5-Conversion!$B$16,2020,2050),Report_Scenarios!$A$7:$A$13,1)+1,7))-INDEX(Report_Scenarios!$C$7:$C$13,MATCH(MEDIAN($B5-Conversion!$B$16,2020,2050),Report_Scenarios!$A$7:$A$13,1)))*(MEDIAN($B5-Conversion!$B$16,2020,2050)-INDEX(Report_Scenarios!$A$7:$A$13,MATCH(MEDIAN($B5-Conversion!$B$16,2020,2050),Report_Scenarios!$A$7:$A$13,1)))/(INDEX(Report_Scenarios!$A$7:$A$13,MIN(MATCH(MEDIAN($B5-Conversion!$B$16,2020,2050),Report_Scenarios!$A$7:$A$13,1)+1,7))-INDEX(Report_Scenarios!$A$7:$A$13,MATCH(MEDIAN($B5-Conversion!$B$16,2020,2050),Report_Scenarios!$A$7:$A$13,1)))),IF($D5="Central",IF(INDEX(Report_Scenarios!$A$18:$A$24,MIN(MATCH(MEDIAN($B5-Conversion!$B$16,2020,2050),Report_Scenarios!$A$18:$A$24,1)+1,7))=INDEX(Report_Scenarios!$A$18:$A$24,MATCH(MEDIAN($B5-Conversion!$B$16,2020,2050),Report_Scenarios!$A$18:$A$24,1)),INDEX(Report_Scenarios!$C$18:$C$24,MATCH(MEDIAN($B5-Conversion!$B$16,2020,2050),Report_Scenarios!$A$18:$A$24,1)),INDEX(Report_Scenarios!$C$18:$C$24,MATCH(MEDIAN($B5-Conversion!$B$16,2020,2050),Report_Scenarios!$A$18:$A$24,1))+(INDEX(Report_Scenarios!$C$18:$C$24,MIN(MATCH(MEDIAN($B5-Conversion!$B$16,2020,2050),Report_Scenarios!$A$18:$A$24,1)+1,7))-INDEX(Report_Scenarios!$C$18:$C$24,MATCH(MEDIAN($B5-Conversion!$B$16,2020,2050),Report_Scenarios!$A$18:$A$24,1)))*(MEDIAN($B5-Conversion!$B$16,2020,2050)-INDEX(Report_Scenarios!$A$18:$A$24,MATCH(MEDIAN($B5-Conversion!$B$16,2020,2050),Report_Scenarios!$A$18:$A$24,1)))/(INDEX(Report_Scenarios!$A$18:$A$24,MIN(MATCH(MEDIAN($B5-Conversion!$B$16,2020,2050),Report_Scenarios!$A$18:$A$24,1)+1,7))-INDEX(Report_Scenarios!$A$18:$A$24,MATCH(MEDIAN($B5-Conversion!$B$16,2020,2050),Report_Scenarios!$A$18:$A$24,1)))),IF(INDEX(Report_Scenarios!$A$29:$A$35,MIN(MATCH(MEDIAN($B5-Conversion!$B$16,2020,2050),Report_Scenarios!$A$29:$A$35,1)+1,7))=INDEX(Report_Scenarios!$A$29:$A$35,MATCH(MEDIAN($B5-Conversion!$B$16,2020,2050),Report_Scenarios!$A$29:$A$35,1)),INDEX(Report_Scenarios!$C$29:$C$35,MATCH(MEDIAN($B5-Conversion!$B$16,2020,2050),Report_Scenarios!$A$29:$A$35,1)),INDEX(Report_Scenarios!$C$29:$C$35,MATCH(MEDIAN($B5-Conversion!$B$16,2020,2050),Report_Scenarios!$A$29:$A$35,1))+(INDEX(Report_Scenarios!$C$29:$C$35,MIN(MATCH(MEDIAN($B5-Conversion!$B$16,2020,2050),Report_Scenarios!$A$29:$A$35,1)+1,7))-INDEX(Report_Scenarios!$C$29:$C$35,MATCH(MEDIAN($B5-Conversion!$B$16,2020,2050),Report_Scenarios!$A$29:$A$35,1)))*(MEDIAN($B5-Conversion!$B$16,2020,2050)-INDEX(Report_Scenarios!$A$29:$A$35,MATCH(MEDIAN($B5-Conversion!$B$16,2020,2050),Report_Scenarios!$A$29:$A$35,1)))/(INDEX(Report_Scenarios!$A$29:$A$35,MIN(MATCH(MEDIAN($B5-Conversion!$B$16,2020,2050),Report_Scenarios!$A$29:$A$35,1)+1,7))-INDEX(Report_Scenarios!$A$29:$A$35,MATCH(MEDIAN($B5-Conversion!$B$16,2020,2050),Report_Scenarios!$A$29:$A$35,1)))))) | G5: =IF($D5="Conservative",IF(INDEX(Report_Scenarios!$A$7:$A$13,MIN(MATCH(MEDIAN($B5-Conversion!$B$16,2020,2050),Report_Scenarios!$A$7:$A$13,1)+1,7))=INDEX(Report_Scenarios!$A$7:$A$13,MATCH(MEDIAN($B5-Conversion!$B$16,2020,2050),Report_Scenarios!$A$7:$A$13,1)),INDEX(Report_Scenarios!$D$7:$D$13,MATCH(MEDIAN($B5-Conversion!$B$16,2020,2050),Report_Scenarios!$A$7:$A$13,1)),INDEX(Report_Scenarios!$D$7:$D$13,MATCH(MEDIAN($B5-Conversion!$B$16,2020,2050),Report_Scenarios!$A$7:$A$13,1))+(INDEX(Report_Scenarios!$D$7:$D$13,MIN(MATCH(MEDIAN($B5-Conversion!$B$16,2020,2050),Report_Scenarios!$A$7:$A$13,1)+1,7))-INDEX(Report_Scenarios!$D$7:$D$13,MATCH(MEDIAN($B5-Conversion!$B$16,2020,2050),Report_Scenarios!$A$7:$A$13,1)))*(MEDIAN($B5-Conversion!$B$16,2020,2050)-INDEX(Report_Scenarios!$A$7:$A$13,MATCH(MEDIAN($B5-Conversion!$B$16,2020,2050),Report_Scenarios!$A$7:$A$13,1)))/(INDEX(Report_Scenarios!$A$7:$A$13,MIN(MATCH(MEDIAN($B5-Conversion!$B$16,2020,2050),Report_Scenarios!$A$7:$A$13,1)+1,7))-INDEX(Report_Scenarios!$A$7:$A$13,MATCH(MEDIAN($B5-Conversion!$B$16,2020,2050),Report_Scenarios!$A$7:$A$13,1)))),IF($D5="Central",IF(INDEX(Report_Scenarios!$A$18:$A$24,MIN(MATCH(MEDIAN($B5-Conversion!$B$16,2020,2050),Report_Scenarios!$A$18:$A$24,1)+1,7))=INDEX(Report_Scenarios!$A$18:$A$24,MATCH(MEDIAN($B5-Conversion!$B$16,2020,2050),Report_Scenarios!$A$18:$A$24,1)),INDEX(Report_Scenarios!$D$18:$D$24,MATCH(MEDIAN($B5-Conversion!$B$16,2020,2050),Report_Scenarios!$A$18:$A$24,1)),INDEX(Report_Scenarios!$D$18:$D$24,MATCH(MEDIAN($B5-Conversion!$B$16,2020,2050),Report_Scenarios!$A$18:$A$24,1))+(INDEX(Report_Scenarios!$D$18:$D$24,MIN(MATCH(MEDIAN($B5-Conversion!$B$16,2020,2050),Report_Scenarios!$A$18:$A$24,1)+1,7))-INDEX(Report_Scenarios!$D$18:$D$24,MATCH(MEDIAN($B5-Conversion!$B$16,2020,2050),Report_Scenarios!$A$18:$A$24,1)))*(MEDIAN($B5-Conversion!$B$16,2020,2050)-INDEX(Report_Scenarios!$A$18:$A$24,MATCH(MEDIAN($B5-Conversion!$B$16,2020,2050),Report_Scenarios!$A$18:$A$24,1)))/(INDEX(Report_Scenarios!$A$18:$A$24,MIN(MATCH(MEDIAN($B5-Conversion!$B$16,2020,2050),Report_Scenarios!$A$18:$A$24,1)+1,7))-INDEX(Report_Scenarios!$A$18:$A$24,MATCH(MEDIAN($B5-Conversion!$B$16,2020,2050),Report_Scenarios!$A$18:$A$24,1)))),IF(INDEX(Report_Scenarios!$A$29:$A$35,MIN(MATCH(MEDIAN($B5-Conversion!$B$16,2020,2050),Report_Scenarios!$A$29:$A$35,1)+1,7))=INDEX(Report_Scenarios!$A$29:$A$35,MATCH(MEDIAN($B5-Conversion!$B$16,2020,2050),Report_Scenarios!$A$29:$A$35,1)),INDEX(Report_Scenarios!$D$29:$D$35,MATCH(MEDIAN($B5-Conversion!$B$16,2020,2050),Report_Scenarios!$A$29:$A$35,1)),INDEX(Report_Scenarios!$D$29:$D$35,MATCH(MEDIAN($B5-Conversion!$B$16,2020,2050),Report_Scenarios!$A$29:$A$35,1))+(INDEX(Report_Scenarios!$D$29:$D$35,MIN(MATCH(MEDIAN($B5-Conversion!$B$16,2020,2050),Report_Scenarios!$A$29:$A$35,1)+1,7))-INDEX(Report_Scenarios!$D$29:$D$35,MATCH(MEDIAN($B5-Conversion!$B$16,2020,2050),Report_Scenarios!$A$29:$A$35,1)))*(MEDIAN($B5-Conversion!$B$16,2020,2050)-INDEX(Report_Scenarios!$A$29:$A$35,MATCH(MEDIAN($B5-Conversion!$B$16,2020,2050),Report_Scenarios!$A$29:$A$35,1)))/(INDEX(Report_Scenarios!$A$29:$A$35,MIN(MATCH(MEDIAN($B5-Conversion!$B$16,2020,2050),Report_Scenarios!$A$29:$A$35,1)+1,7))-INDEX(Report_Scenarios!$A$29:$A$35,MATCH(MEDIAN($B5-Conversion!$B$16,2020,2050),Report_Scenarios!$A$29:$A$35,1)))))) | H5: =IF($D5="Conservative",IF(INDEX(Report_Scenarios!$A$7:$A$13,MIN(MATCH(MEDIAN($B5-Conversion!$B$16,2020,2050),Report_Scenarios!$A$7:$A$13,1)+1,7))=INDEX(Report_Scenarios!$A$7:$A$13,MATCH(MEDIAN($B5-Conversion!$B$16,2020,2050),Report_Scenarios!$A$7:$A$13,1)),INDEX(Report_Scenarios!$E$7:$E$13,MATCH(MEDIAN($B5-Conversion!$B$16,2020,2050),Report_Scenarios!$A$7:$A$13,1)),INDEX(Report_Scenarios!$E$7:$E$13,MATCH(MEDIAN($B5-Conversion!$B$16,2020,2050),Report_Scenarios!$A$7:$A$13,1))+(INDEX(Report_Scenarios!$E$7:$E$13,MIN(MATCH(MEDIAN($B5-Conversion!$B$16,2020,2050),Report_Scenarios!$A$7:$A$13,1)+1,7))-INDEX(Report_Scenarios!$E$7:$E$13,MATCH(MEDIAN($B5-Conversion!$B$16,2020,2050),Report_Scenarios!$A$7:$A$13,1)))*(MEDIAN($B5-Conversion!$B$16,2020,2050)-INDEX(Report_Scenarios!$A$7:$A$13,MATCH(MEDIAN($B5-Conversion!$B$16,2020,2050),Report_Scenarios!$A$7:$A$13,1)))/(INDEX(Report_Scenarios!$A$7:$A$13,MIN(MATCH(MEDIAN($B5-Conversion!$B$16,2020,2050),Report_Scenarios!$A$7:$A$13,1)+1,7))-INDEX(Report_Scenarios!$A$7:$A$13,MATCH(MEDIAN($B5-Conversion!$B$16,2020,2050),Report_Scenarios!$A$7:$A$13,1)))),IF($D5="Central",IF(INDEX(Report_Scenarios!$A$18:$A$24,MIN(MATCH(MEDIAN($B5-Conversion!$B$16,2020,2050),Report_Scenarios!$A$18:$A$24,1)+1,7))=INDEX(Report_Scenarios!$A$18:$A$24,MATCH(MEDIAN($B5-Conversion!$B$16,2020,2050),Report_Scenarios!$A$18:$A$24,1)),INDEX(Report_Scenarios!$E$18:$E$24,MATCH(MEDIAN($B5-Conversion!$B$16,2020,2050),Report_Scenarios!$A$18:$A$24,1)),INDEX(Report_Scenarios!$E$18:$E$24,MATCH(MEDIAN($B5-Conversion!$B$16,2020,2050),Report_Scenarios!$A$18:$A$24,1))+(INDEX(Report_Scenarios!$E$18:$E$24,MIN(MATCH(MEDIAN($B5-Conversion!$B$16,2020,2050),Report_Scenarios!$A$18:$A$24,1)+1,7))-INDEX(Report_Scenarios!$E$18:$E$24,MATCH(MEDIAN($B5-Conversion!$B$16,2020,2050),Report_Scenarios!$A$18:$A$24,1)))*(MEDIAN($B5-Conversion!$B$16,2020,2050)-INDEX(Report_Scenarios!$A$18:$A$24,MATCH(MEDIAN($B5-Conversion!$B$16,2020,2050),Report_Scenarios!$A$18:$A$24,1)))/(INDEX(Report_Scenarios!$A$18:$A$24,MIN(MATCH(MEDIAN($B5-Conversion!$B$16,2020,2050),Report_Scenarios!$A$18:$A$24,1)+1,7))-INDEX(Report_Scenarios!$A$18:$A$24,MATCH(MEDIAN($B5-Conversion!$B$16,2020,2050),Report_Scenarios!$A$18:$A$24,1)))),IF(INDEX(Report_Scenarios!$A$29:$A$35,MIN(MATCH(MEDIAN($B5-Conversion!$B$16,2020,2050),Report_Scenarios!$A$29:$A$35,1)+1,7))=INDEX(Report_Scenarios!$A$29:$A$35,MATCH(MEDIAN($B5-Conversion!$B$16,2020,2050),Report_Scenarios!$A$29:$A$35,1)),INDEX(Report_Scenarios!$E$29:$E$35,MATCH(MEDIAN($B5-Conversion!$B$16,2020,2050),Report_Scenarios!$A$29:$A$35,1)),INDEX(Report_Scenarios!$E$29:$E$35,MATCH(MEDIAN($B5-Conversion!$B$16,2020,2050),Report_Scenarios!$A$29:$A$35,1))+(INDEX(Report_Scenarios!$E$29:$E$35,MIN(MATCH(MEDIAN($B5-Conversion!$B$16,2020,2050),Report_Scenarios!$A$29:$A$35,1)+1,7))-INDEX(Report_Scenarios!$E$29:$E$35,MATCH(MEDIAN($B5-Conversion!$B$16,2020,2050),Report_Scenarios!$A$29:$A$35,1)))*(MEDIAN($B5-Conversion!$B$16,2020,2050)-INDEX(Report_Scenarios!$A$29:$A$35,MATCH(MEDIAN($B5-Conversion!$B$16,2020,2050),Report_Scenarios!$A$29:$A$35,1)))/(INDEX(Report_Scenarios!$A$29:$A$35,MIN(MATCH(MEDIAN($B5-Conversion!$B$16,2020,2050),Report_Scenarios!$A$29:$A$35,1)+1,7))-INDEX(Report_Scenarios!$A$29:$A$35,MATCH(MEDIAN($B5-Conversion!$B$16,2020,2050),Report_Scenarios!$A$29:$A$35,1)))))) | I5: =IF($D5="Conservative",IF(INDEX(Report_Scenarios!$A$7:$A$13,MIN(MATCH(MEDIAN($B5-Conversion!$B$16,2020,2050),Report_Scenarios!$A$7:$A$13,1)+1,7))=INDEX(Report_Scenarios!$A$7:$A$13,MATCH(MEDIAN($B5-Conversion!$B$16,2020,2050),Report_Scenarios!$A$7:$A$13,1)),INDEX(Report_Scenarios!$F$7:$F$13,MATCH(MEDIAN($B5-Conversion!$B$16,2020,2050),Report_Scenarios!$A$7:$A$13,1)),INDEX(Report_Scenarios!$F$7:$F$13,MATCH(MEDIAN($B5-Conversion!$B$16,2020,2050),Report_Scenarios!$A$7:$A$13,1))+(INDEX(Report_Scenarios!$F$7:$F$13,MIN(MATCH(MEDIAN($B5-Conversion!$B$16,2020,2050),Report_Scenarios!$A$7:$A$13,1)+1,7))-INDEX(Report_Scenarios!$F$7:$F$13,MATCH(MEDIAN($B5-Conversion!$B$16,2020,2050),Report_Scenarios!$A$7:$A$13,1)))*(MEDIAN($B5-Conversion!$B$16,2020,2050)-INDEX(Report_Scenarios!$A$7:$A$13,MATCH(MEDIAN($B5-Conversion!$B$16,2020,2050),Report_Scenarios!$A$7:$A$13,1)))/(INDEX(Report_Scenarios!$A$7:$A$13,MIN(MATCH(MEDIAN($B5-Conversion!$B$16,2020,2050),Report_Scenarios!$A$7:$A$13,1)+1,7))-INDEX(Report_Scenarios!$A$7:$A$13,MATCH(MEDIAN($B5-Conversion!$B$16,2020,2050),Report_Scenarios!$A$7:$A$13,1)))),IF($D5="Central",IF(INDEX(Report_Scenarios!$A$18:$A$24,MIN(MATCH(MEDIAN($B5-Conversion!$B$16,2020,2050),Report_Scenarios!$A$18:$A$24,1)+1,7))=INDEX(Report_Scenarios!$A$18:$A$24,MATCH(MEDIAN($B5-Conversion!$B$16,2020,2050),Report_Scenarios!$A$18:$A$24,1)),INDEX(Report_Scenarios!$F$18:$F$24,MATCH(MEDIAN($B5-Conversion!$B$16,2020,2050),Report_Scenarios!$A$18:$A$24,1)),INDEX(Report_Scenarios!$F$18:$F$24,MATCH(MEDIAN($B5-Conversion!$B$16,2020,2050),Report_Scenarios!$A$18:$A$24,1))+(INDEX(Report_Scenarios!$F$18:$F$24,MIN(MATCH(MEDIAN($B5-Conversion!$B$16,2020,2050),Report_Scenarios!$A$18:$A$24,1)+1,7))-INDEX(Report_Scenarios!$F$18:$F$24,MATCH(MEDIAN($B5-Conversion!$B$16,2020,2050),Report_Scenarios!$A$18:$A$24,1)))*(MEDIAN($B5-Conversion!$B$16,2020,2050)-INDEX(Report_Scenarios!$A$18:$A$24,MATCH(MEDIAN($B5-Conversion!$B$16,2020,2050),Report_Scenarios!$A$18:$A$24,1)))/(INDEX(Report_Scenarios!$A$18:$A$24,MIN(MATCH(MEDIAN($B5-Conversion!$B$16,2020,2050),Report_Scenarios!$A$18:$A$24,1)+1,7))-INDEX(Report_Scenarios!$A$18:$A$24,MATCH(MEDIAN($B5-Conversion!$B$16,2020,2050),Report_Scenarios!$A$18:$A$24,1)))),IF(INDEX(Report_Scenarios!$A$29:$A$35,MIN(MATCH(MEDIAN($B5-Conversion!$B$16,2020,2050),Report_Scenarios!$A$29:$A$35,1)+1,7))=INDEX(Report_Scenarios!$A$29:$A$35,MATCH(MEDIAN($B5-Conversion!$B$16,2020,2050),Report_Scenarios!$A$29:$A$35,1)),INDEX(Report_Scenarios!$F$29:$F$35,MATCH(MEDIAN($B5-Conversion!$B$16,2020,2050),Report_Scenarios!$A$29:$A$35,1)),INDEX(Report_Scenarios!$F$29:$F$35,MATCH(MEDIAN($B5-Conversion!$B$16,2020,2050),Report_Scenarios!$A$29:$A$35,1))+(INDEX(Report_Scenarios!$F$29:$F$35,MIN(MATCH(MEDIAN($B5-Conversion!$B$16,2020,2050),Report_Scenarios!$A$29:$A$35,1)+1,7))-INDEX(Report_Scenarios!$F$29:$F$35,MATCH(MEDIAN($B5-Conversion!$B$16,2020,2050),Report_Scenarios!$A$29:$A$35,1)))*(MEDIAN($B5-Conversion!$B$16,2020,2050)-INDEX(Report_Scenarios!$A$29:$A$35,MATCH(MEDIAN($B5-Conversion!$B$16,2020,2050),Report_Scenarios!$A$29:$A$35,1)))/(INDEX(Report_Scenarios!$A$29:$A$35,MIN(MATCH(MEDIAN($B5-Conversion!$B$16,2020,2050),Report_Scenarios!$A$29:$A$35,1)+1,7))-INDEX(Report_Scenarios!$A$29:$A$35,MATCH(MEDIAN($B5-Conversion!$B$16,2020,2050),Report_Scenarios!$A$29:$A$35,1)))))) | J5: =IF($D5="Conservative",IF(INDEX(Report_Scenarios!$A$7:$A$13,MIN(MATCH(MEDIAN($B5-Conversion!$B$16,2020,2050),Report_Scenarios!$A$7:$A$13,1)+1,7))=INDEX(Report_Scenarios!$A$7:$A$13,MATCH(MEDIAN($B5-Conversion!$B$16,2020,2050),Report_Scenarios!$A$7:$A$13,1)),INDEX(Report_Scenarios!$G$7:$G$13,MATCH(MEDIAN($B5-Conversion!$B$16,2020,2050),Report_Scenarios!$A$7:$A$13,1)),INDEX(Report_Scenarios!$G$7:$G$13,MATCH(MEDIAN($B5-Conversion!$B$16,2020,2050),Report_Scenarios!$A$7:$A$13,1))+(INDEX(Report_Scenarios!$G$7:$G$13,MIN(MATCH(MEDIAN($B5-Conversion!$B$16,2020,2050),Report_Scenarios!$A$7:$A$13,1)+1,7))-INDEX(Report_Scenarios!$G$7:$G$13,MATCH(MEDIAN($B5-Conversion!$B$16,2020,2050),Report_Scenarios!$A$7:$A$13,1)))*(MEDIAN($B5-Conversion!$B$16,2020,2050)-INDEX(Report_Scenarios!$A$7:$A$13,MATCH(MEDIAN($B5-Conversion!$B$16,2020,2050),Report_Scenarios!$A$7:$A$13,1)))/(INDEX(Report_Scenarios!$A$7:$A$13,MIN(MATCH(MEDIAN($B5-Conversion!$B$16,2020,2050),Report_Scenarios!$A$7:$A$13,1)+1,7))-INDEX(Report_Scenarios!$A$7:$A$13,MATCH(MEDIAN($B5-Conversion!$B$16,2020,2050),Report_Scenarios!$A$7:$A$13,1)))),IF($D5="Central",IF(INDEX(Report_Scenarios!$A$18:$A$24,MIN(MATCH(MEDIAN($B5-Conversion!$B$16,2020,2050),Report_Scenarios!$A$18:$A$24,1)+1,7))=INDEX(Report_Scenarios!$A$18:$A$24,MATCH(MEDIAN($B5-Conversion!$B$16,2020,2050),Report_Scenarios!$A$18:$A$24,1)),INDEX(Report_Scenarios!$G$18:$G$24,MATCH(MEDIAN($B5-Conversion!$B$16,2020,2050),Report_Scenarios!$A$18:$A$24,1)),INDEX(Report_Scenarios!$G$18:$G$24,MATCH(MEDIAN($B5-Conversion!$B$16,2020,2050),Report_Scenarios!$A$18:$A$24,1))+(INDEX(Report_Scenarios!$G$18:$G$24,MIN(MATCH(MEDIAN($B5-Conversion!$B$16,2020,2050),Report_Scenarios!$A$18:$A$24,1)+1,7))-INDEX(Report_Scenarios!$G$18:$G$24,MATCH(MEDIAN($B5-Conversion!$B$16,2020,2050),Report_Scenarios!$A$18:$A$24,1)))*(MEDIAN($B5-Conversion!$B$16,2020,2050)-INDEX(Report_Scenarios!$A$18:$A$24,MATCH(MEDIAN($B5-Conversion!$B$16,2020,2050),Report_Scenarios!$A$18:$A$24,1)))/(INDEX(Report_Scenarios!$A$18:$A$24,MIN(MATCH(MEDIAN($B5-Conversion!$B$16,2020,2050),Report_Scenarios!$A$18:$A$24,1)+1,7))-INDEX(Report_Scenarios!$A$18:$A$24,MATCH(MEDIAN($B5-Conversion!$B$16,2020,2050),Report_Scenarios!$A$18:$A$24,1)))),IF(INDEX(Report_Scenarios!$A$29:$A$35,MIN(MATCH(MEDIAN($B5-Conversion!$B$16,2020,2050),Report_Scenarios!$A$29:$A$35,1)+1,7))=INDEX(Report_Scenarios!$A$29:$A$35,MATCH(MEDIAN($B5-Conversion!$B$16,2020,2050),Report_Scenarios!$A$29:$A$35,1)),INDEX(Report_Scenarios!$G$29:$G$35,MATCH(MEDIAN($B5-Conversion!$B$16,2020,2050),Report_Scenarios!$A$29:$A$35,1)),INDEX(Report_Scenarios!$G$29:$G$35,MATCH(MEDIAN($B5-Conversion!$B$16,2020,2050),Report_Scenarios!$A$29:$A$35,1))+(INDEX(Report_Scenarios!$G$29:$G$35,MIN(MATCH(MEDIAN($B5-Conversion!$B$16,2020,2050),Report_Scenarios!$A$29:$A$35,1)+1,7))-INDEX(Report_Scenarios!$G$29:$G$35,MATCH(MEDIAN($B5-Conversion!$B$16,2020,2050),Report_Scenarios!$A$29:$A$35,1)))*(MEDIAN($B5-Conversion!$B$16,2020,2050)-INDEX(Report_Scenarios!$A$29:$A$35,MATCH(MEDIAN($B5-Conversion!$B$16,2020,2050),Report_Scenarios!$A$29:$A$35,1)))/(INDEX(Report_Scenarios!$A$29:$A$35,MIN(MATCH(MEDIAN($B5-Conversion!$B$16,2020,2050),Report_Scenarios!$A$29:$A$35,1)+1,7))-INDEX(Report_Scenarios!$A$29:$A$35,MATCH(MEDIAN($B5-Conversion!$B$16,2020,2050),Report_Scenarios!$A$29:$A$35,1)))))) | K5: =SUM(E5:J5) | L5: =IF(R5<>"",R5,IF($K5=0,0,E5/$K5)) | M5: =IF(S5<>"",S5,IF($K5=0,0,F5/$K5)) | N5: =IF(T5<>"",T5,IF($K5=0,0,G5/$K5)) | O5: =IF(U5<>"",U5,IF($K5=0,0,H5/$K5)) | P5: =IF(V5<>"",V5,IF($K5=0,0,I5/$K5)) | Q5: =IF(W5<>"",W5,IF($K5=0,0,J5/$K5))
A6: AB | B6: 2020 | C6: Share_Mode | D6: =Conversion!$B$19 | E6: =IF($D6="Conservative",IF(INDEX(Report_Scenarios!$A$7:$A$13,MIN(MATCH(MEDIAN($B6-Conversion!$B$16,2020,2050),Report_Scenarios!$A$7:$A$13,1)+1,7))=INDEX(Report_Scenarios!$A$7:$A$13,MATCH(MEDIAN($B6-Conversion!$B$16,2020,2050),Report_Scenarios!$A$7:$A$13,1)),INDEX(Report_Scenarios!$B$7:$B$13,MATCH(MEDIAN($B6-Conversion!$B$16,2020,2050),Report_Scenarios!$A$7:$A$13,1)),INDEX(Report_Scenarios!$B$7:$B$13,MATCH(MEDIAN($B6-Conversion!$B$16,2020,2050),Report_Scenarios!$A$7:$A$13,1))+(INDEX(Report_Scenarios!$B$7:$B$13,MIN(MATCH(MEDIAN($B6-Conversion!$B$16,2020,2050),Report_Scenarios!$A$7:$A$13,1)+1,7))-INDEX(Report_Scenarios!$B$7:$B$13,MATCH(MEDIAN($B6-Conversion!$B$16,2020,2050),Report_Scenarios!$A$7:$A$13,1)))*(MEDIAN($B6-Conversion!$B$16,2020,2050)-INDEX(Report_Scenarios!$A$7:$A$13,MATCH(MEDIAN($B6-Conversion!$B$16,2020,2050),Report_Scenarios!$A$7:$A$13,1)))/(INDEX(Report_Scenarios!$A$7:$A$13,MIN(MATCH(MEDIAN($B6-Conversion!$B$16,2020,2050),Report_Scenarios!$A$7:$A$13,1)+1,7))-INDEX(Report_Scenarios!$A$7:$A$13,MATCH(MEDIAN($B6-Conversion!$B$16,2020,2050),Report_Scenarios!$A$7:$A$13,1)))),IF($D6="Central",IF(INDEX(Report_Scenarios!$A$18:$A$24,MIN(MATCH(MEDIAN($B6-Conversion!$B$16,2020,2050),Report_Scenarios!$A$18:$A$24,1)+1,7))=INDEX(Report_Scenarios!$A$18:$A$24,MATCH(MEDIAN($B6-Conversion!$B$16,2020,2050),Report_Scenarios!$A$18:$A$24,1)),INDEX(Report_Scenarios!$B$18:$B$24,MATCH(MEDIAN($B6-Conversion!$B$16,2020,2050),Report_Scenarios!$A$18:$A$24,1)),INDEX(Report_Scenarios!$B$18:$B$24,MATCH(MEDIAN($B6-Conversion!$B$16,2020,2050),Report_Scenarios!$A$18:$A$24,1))+(INDEX(Report_Scenarios!$B$18:$B$24,MIN(MATCH(MEDIAN($B6-Conversion!$B$16,2020,2050),Report_Scenarios!$A$18:$A$24,1)+1,7))-INDEX(Report_Scenarios!$B$18:$B$24,MATCH(MEDIAN($B6-Conversion!$B$16,2020,2050),Report_Scenarios!$A$18:$A$24,1)))*(MEDIAN($B6-Conversion!$B$16,2020,2050)-INDEX(Report_Scenarios!$A$18:$A$24,MATCH(MEDIAN($B6-Conversion!$B$16,2020,2050),Report_Scenarios!$A$18:$A$24,1)))/(INDEX(Report_Scenarios!$A$18:$A$24,MIN(MATCH(MEDIAN($B6-Conversion!$B$16,2020,2050),Report_Scenarios!$A$18:$A$24,1)+1,7))-INDEX(Report_Scenarios!$A$18:$A$24,MATCH(MEDIAN($B6-Conversion!$B$16,2020,2050),Report_Scenarios!$A$18:$A$24,1)))),IF(INDEX(Report_Scenarios!$A$29:$A$35,MIN(MATCH(MEDIAN($B6-Conversion!$B$16,2020,2050),Report_Scenarios!$A$29:$A$35,1)+1,7))=INDEX(Report_Scenarios!$A$29:$A$35,MATCH(MEDIAN($B6-Conversion!$B$16,2020,2050),Report_Scenarios!$A$29:$A$35,1)),INDEX(Report_Scenarios!$B$29:$B$35,MATCH(MEDIAN($B6-Conversion!$B$16,2020,2050),Report_Scenarios!$A$29:$A$35,1)),INDEX(Report_Scenarios!$B$29:$B$35,MATCH(MEDIAN($B6-Conversion!$B$16,2020,2050),Report_Scenarios!$A$29:$A$35,1))+(INDEX(Report_Scenarios!$B$29:$B$35,MIN(MATCH(MEDIAN($B6-Conversion!$B$16,2020,2050),Report_Scenarios!$A$29:$A$35,1)+1,7))-INDEX(Report_Scenarios!$B$29:$B$35,MATCH(MEDIAN($B6-Conversion!$B$16,2020,2050),Report_Scenarios!$A$29:$A$35,1)))*(MEDIAN($B6-Conversion!$B$16,2020,2050)-INDEX(Report_Scenarios!$A$29:$A$35,MATCH(MEDIAN($B6-Conversion!$B$16,2020,2050),Report_Scenarios!$A$29:$A$35,1)))/(INDEX(Report_Scenarios!$A$29:$A$35,MIN(MATCH(MEDIAN($B6-Conversion!$B$16,2020,2050),Report_Scenarios!$A$29:$A$35,1)+1,7))-INDEX(Report_Scenarios!$A$29:$A$35,MATCH(MEDIAN($B6-Conversion!$B$16,2020,2050),Report_Scenarios!$A$29:$A$35,1)))))) | F6: =IF($D6="Conservative",IF(INDEX(Report_Scenarios!$A$7:$A$13,MIN(MATCH(MEDIAN($B6-Conversion!$B$16,2020,2050),Report_Scenarios!$A$7:$A$13,1)+1,7))=INDEX(Report_Scenarios!$A$7:$A$13,MATCH(MEDIAN($B6-Conversion!$B$16,2020,2050),Report_Scenarios!$A$7:$A$13,1)),INDEX(Report_Scenarios!$C$7:$C$13,MATCH(MEDIAN($B6-Conversion!$B$16,2020,2050),Report_Scenarios!$A$7:$A$13,1)),INDEX(Report_Scenarios!$C$7:$C$13,MATCH(MEDIAN($B6-Conversion!$B$16,2020,2050),Report_Scenarios!$A$7:$A$13,1))+(INDEX(Report_Scenarios!$C$7:$C$13,MIN(MATCH(MEDIAN($B6-Conversion!$B$16,2020,2050),Report_Scenarios!$A$7:$A$13,1)+1,7))-INDEX(Report_Scenarios!$C$7:$C$13,MATCH(MEDIAN($B6-Conversion!$B$16,2020,2050),Report_Scenarios!$A$7:$A$13,1)))*(MEDIAN($B6-Conversion!$B$16,2020,2050)-INDEX(Report_Scenarios!$A$7:$A$13,MATCH(MEDIAN($B6-Conversion!$B$16,2020,2050),Report_Scenarios!$A$7:$A$13,1)))/(INDEX(Report_Scenarios!$A$7:$A$13,MIN(MATCH(MEDIAN($B6-Conversion!$B$16,2020,2050),Report_Scenarios!$A$7:$A$13,1)+1,7))-INDEX(Report_Scenarios!$A$7:$A$13,MATCH(MEDIAN($B6-Conversion!$B$16,2020,2050),Report_Scenarios!$A$7:$A$13,1)))),IF($D6="Central",IF(INDEX(Report_Scenarios!$A$18:$A$24,MIN(MATCH(MEDIAN($B6-Conversion!$B$16,2020,2050),Report_Scenarios!$A$18:$A$24,1)+1,7))=INDEX(Report_Scenarios!$A$18:$A$24,MATCH(MEDIAN($B6-Conversion!$B$16,2020,2050),Report_Scenarios!$A$18:$A$24,1)),INDEX(Report_Scenarios!$C$18:$C$24,MATCH(MEDIAN($B6-Conversion!$B$16,2020,2050),Report_Scenarios!$A$18:$A$24,1)),INDEX(Report_Scenarios!$C$18:$C$24,MATCH(MEDIAN($B6-Conversion!$B$16,2020,2050),Report_Scenarios!$A$18:$A$24,1))+(INDEX(Report_Scenarios!$C$18:$C$24,MIN(MATCH(MEDIAN($B6-Conversion!$B$16,2020,2050),Report_Scenarios!$A$18:$A$24,1)+1,7))-INDEX(Report_Scenarios!$C$18:$C$24,MATCH(MEDIAN($B6-Conversion!$B$16,2020,2050),Report_Scenarios!$A$18:$A$24,1)))*(MEDIAN($B6-Conversion!$B$16,2020,2050)-INDEX(Report_Scenarios!$A$18:$A$24,MATCH(MEDIAN($B6-Conversion!$B$16,2020,2050),Report_Scenarios!$A$18:$A$24,1)))/(INDEX(Report_Scenarios!$A$18:$A$24,MIN(MATCH(MEDIAN($B6-Conversion!$B$16,2020,2050),Report_Scenarios!$A$18:$A$24,1)+1,7))-INDEX(Report_Scenarios!$A$18:$A$24,MATCH(MEDIAN($B6-Conversion!$B$16,2020,2050),Report_Scenarios!$A$18:$A$24,1)))),IF(INDEX(Report_Scenarios!$A$29:$A$35,MIN(MATCH(MEDIAN($B6-Conversion!$B$16,2020,2050),Report_Scenarios!$A$29:$A$35,1)+1,7))=INDEX(Report_Scenarios!$A$29:$A$35,MATCH(MEDIAN($B6-Conversion!$B$16,2020,2050),Report_Scenarios!$A$29:$A$35,1)),INDEX(Report_Scenarios!$C$29:$C$35,MATCH(MEDIAN($B6-Conversion!$B$16,2020,2050),Report_Scenarios!$A$29:$A$35,1)),INDEX(Report_Scenarios!$C$29:$C$35,MATCH(MEDIAN($B6-Conversion!$B$16,2020,2050),Report_Scenarios!$A$29:$A$35,1))+(INDEX(Report_Scenarios!$C$29:$C$35,MIN(MATCH(MEDIAN($B6-Conversion!$B$16,2020,2050),Report_Scenarios!$A$29:$A$35,1)+1,7))-INDEX(Report_Scenarios!$C$29:$C$35,MATCH(MEDIAN($B6-Conversion!$B$16,2020,2050),Report_Scenarios!$A$29:$A$35,1)))*(MEDIAN($B6-Conversion!$B$16,2020,2050)-INDEX(Report_Scenarios!$A$29:$A$35,MATCH(MEDIAN($B6-Conversion!$B$16,2020,2050),Report_Scenarios!$A$29:$A$35,1)))/(INDEX(Report_Scenarios!$A$29:$A$35,MIN(MATCH(MEDIAN($B6-Conversion!$B$16,2020,2050),Report_Scenarios!$A$29:$A$35,1)+1,7))-INDEX(Report_Scenarios!$A$29:$A$35,MATCH(MEDIAN($B6-Conversion!$B$16,2020,2050),Report_Scenarios!$A$29:$A$35,1)))))) | G6: =IF($D6="Conservative",IF(INDEX(Report_Scenarios!$A$7:$A$13,MIN(MATCH(MEDIAN($B6-Conversion!$B$16,2020,2050),Report_Scenarios!$A$7:$A$13,1)+1,7))=INDEX(Report_Scenarios!$A$7:$A$13,MATCH(MEDIAN($B6-Conversion!$B$16,2020,2050),Report_Scenarios!$A$7:$A$13,1)),INDEX(Report_Scenarios!$D$7:$D$13,MATCH(MEDIAN($B6-Conversion!$B$16,2020,2050),Report_Scenarios!$A$7:$A$13,1)),INDEX(Report_Scenarios!$D$7:$D$13,MATCH(MEDIAN($B6-Conversion!$B$16,2020,2050),Report_Scenarios!$A$7:$A$13,1))+(INDEX(Report_Scenarios!$D$7:$D$13,MIN(MATCH(MEDIAN($B6-Conversion!$B$16,2020,2050),Report_Scenarios!$A$7:$A$13,1)+1,7))-INDEX(Report_Scenarios!$D$7:$D$13,MATCH(MEDIAN($B6-Conversion!$B$16,2020,2050),Report_Scenarios!$A$7:$A$13,1)))*(MEDIAN($B6-Conversion!$B$16,2020,2050)-INDEX(Report_Scenarios!$A$7:$A$13,MATCH(MEDIAN($B6-Conversion!$B$16,2020,2050),Report_Scenarios!$A$7:$A$13,1)))/(INDEX(Report_Scenarios!$A$7:$A$13,MIN(MATCH(MEDIAN($B6-Conversion!$B$16,2020,2050),Report_Scenarios!$A$7:$A$13,1)+1,7))-INDEX(Report_Scenarios!$A$7:$A$13,MATCH(MEDIAN($B6-Conversion!$B$16,2020,2050),Report_Scenarios!$A$7:$A$13,1)))),IF($D6="Central",IF(INDEX(Report_Scenarios!$A$18:$A$24,MIN(MATCH(MEDIAN($B6-Conversion!$B$16,2020,2050),Report_Scenarios!$A$18:$A$24,1)+1,7))=INDEX(Report_Scenarios!$A$18:$A$24,MATCH(MEDIAN($B6-Conversion!$B$16,2020,2050),Report_Scenarios!$A$18:$A$24,1)),INDEX(Report_Scenarios!$D$18:$D$24,MATCH(MEDIAN($B6-Conversion!$B$16,2020,2050),Report_Scenarios!$A$18:$A$24,1)),INDEX(Report_Scenarios!$D$18:$D$24,MATCH(MEDIAN($B6-Conversion!$B$16,2020,2050),Report_Scenarios!$A$18:$A$24,1))+(INDEX(Report_Scenarios!$D$18:$D$24,MIN(MATCH(MEDIAN($B6-Conversion!$B$16,2020,2050),Report_Scenarios!$A$18:$A$24,1)+1,7))-INDEX(Report_Scenarios!$D$18:$D$24,MATCH(MEDIAN($B6-Conversion!$B$16,2020,2050),Report_Scenarios!$A$18:$A$24,1)))*(MEDIAN($B6-Conversion!$B$16,2020,2050)-INDEX(Report_Scenarios!$A$18:$A$24,MATCH(MEDIAN($B6-Conversion!$B$16,2020,2050),Report_Scenarios!$A$18:$A$24,1)))/(INDEX(Report_Scenarios!$A$18:$A$24,MIN(MATCH(MEDIAN($B6-Conversion!$B$16,2020,2050),Report_Scenarios!$A$18:$A$24,1)+1,7))-INDEX(Report_Scenarios!$A$18:$A$24,MATCH(MEDIAN($B6-Conversion!$B$16,2020,2050),Report_Scenarios!$A$18:$A$24,1)))),IF(INDEX(Report_Scenarios!$A$29:$A$35,MIN(MATCH(MEDIAN($B6-Conversion!$B$16,2020,2050),Report_Scenarios!$A$29:$A$35,1)+1,7))=INDEX(Report_Scenarios!$A$29:$A$35,MATCH(MEDIAN($B6-Conversion!$B$16,2020,2050),Report_Scenarios!$A$29:$A$35,1)),INDEX(Report_Scenarios!$D$29:$D$35,MATCH(MEDIAN($B6-Conversion!$B$16,2020,2050),Report_Scenarios!$A$29:$A$35,1)),INDEX(Report_Scenarios!$D$29:$D$35,MATCH(MEDIAN($B6-Conversion!$B$16,2020,2050),Report_Scenarios!$A$29:$A$35,1))+(INDEX(Report_Scenarios!$D$29:$D$35,MIN(MATCH(MEDIAN($B6-Conversion!$B$16,2020,2050),Report_Scenarios!$A$29:$A$35,1)+1,7))-INDEX(Report_Scenarios!$D$29:$D$35,MATCH(MEDIAN($B6-Conversion!$B$16,2020,2050),Report_Scenarios!$A$29:$A$35,1)))*(MEDIAN($B6-Conversion!$B$16,2020,2050)-INDEX(Report_Scenarios!$A$29:$A$35,MATCH(MEDIAN($B6-Conversion!$B$16,2020,2050),Report_Scenarios!$A$29:$A$35,1)))/(INDEX(Report_Scenarios!$A$29:$A$35,MIN(MATCH(MEDIAN($B6-Conversion!$B$16,2020,2050),Report_Scenarios!$A$29:$A$35,1)+1,7))-INDEX(Report_Scenarios!$A$29:$A$35,MATCH(MEDIAN($B6-Conversion!$B$16,2020,2050),Report_Scenarios!$A$29:$A$35,1)))))) | H6: =IF($D6="Conservative",IF(INDEX(Report_Scenarios!$A$7:$A$13,MIN(MATCH(MEDIAN($B6-Conversion!$B$16,2020,2050),Report_Scenarios!$A$7:$A$13,1)+1,7))=INDEX(Report_Scenarios!$A$7:$A$13,MATCH(MEDIAN($B6-Conversion!$B$16,2020,2050),Report_Scenarios!$A$7:$A$13,1)),INDEX(Report_Scenarios!$E$7:$E$13,MATCH(MEDIAN($B6-Conversion!$B$16,2020,2050),Report_Scenarios!$A$7:$A$13,1)),INDEX(Report_Scenarios!$E$7:$E$13,MATCH(MEDIAN($B6-Conversion!$B$16,2020,2050),Report_Scenarios!$A$7:$A$13,1))+(INDEX(Report_Scenarios!$E$7:$E$13,MIN(MATCH(MEDIAN($B6-Conversion!$B$16,2020,2050),Report_Scenarios!$A$7:$A$13,1)+1,7))-INDEX(Report_Scenarios!$E$7:$E$13,MATCH(MEDIAN($B6-Conversion!$B$16,2020,2050),Report_Scenarios!$A$7:$A$13,1)))*(MEDIAN($B6-Conversion!$B$16,2020,2050)-INDEX(Report_Scenarios!$A$7:$A$13,MATCH(MEDIAN($B6-Conversion!$B$16,2020,2050),Report_Scenarios!$A$7:$A$13,1)))/(INDEX(Report_Scenarios!$A$7:$A$13,MIN(MATCH(MEDIAN($B6-Conversion!$B$16,2020,2050),Report_Scenarios!$A$7:$A$13,1)+1,7))-INDEX(Report_Scenarios!$A$7:$A$13,MATCH(MEDIAN($B6-Conversion!$B$16,2020,2050),Report_Scenarios!$A$7:$A$13,1)))),IF($D6="Central",IF(INDEX(Report_Scenarios!$A$18:$A$24,MIN(MATCH(MEDIAN($B6-Conversion!$B$16,2020,2050),Report_Scenarios!$A$18:$A$24,1)+1,7))=INDEX(Report_Scenarios!$A$18:$A$24,MATCH(MEDIAN($B6-Conversion!$B$16,2020,2050),Report_Scenarios!$A$18:$A$24,1)),INDEX(Report_Scenarios!$E$18:$E$24,MATCH(MEDIAN($B6-Conversion!$B$16,2020,2050),Report_Scenarios!$A$18:$A$24,1)),INDEX(Report_Scenarios!$E$18:$E$24,MATCH(MEDIAN($B6-Conversion!$B$16,2020,2050),Report_Scenarios!$A$18:$A$24,1))+(INDEX(Report_Scenarios!$E$18:$E$24,MIN(MATCH(MEDIAN($B6-Conversion!$B$16,2020,2050),Report_Scenarios!$A$18:$A$24,1)+1,7))-INDEX(Report_Scenarios!$E$18:$E$24,MATCH(MEDIAN($B6-Conversion!$B$16,2020,2050),Report_Scenarios!$A$18:$A$24,1)))*(MEDIAN($B6-Conversion!$B$16,2020,2050)-INDEX(Report_Scenarios!$A$18:$A$24,MATCH(MEDIAN($B6-Conversion!$B$16,2020,2050),Report_Scenarios!$A$18:$A$24,1)))/(INDEX(Report_Scenarios!$A$18:$A$24,MIN(MATCH(MEDIAN($B6-Conversion!$B$16,2020,2050),Report_Scenarios!$A$18:$A$24,1)+1,7))-INDEX(Report_Scenarios!$A$18:$A$24,MATCH(MEDIAN($B6-Conversion!$B$16,2020,2050),Report_Scenarios!$A$18:$A$24,1)))),IF(INDEX(Report_Scenarios!$A$29:$A$35,MIN(MATCH(MEDIAN($B6-Conversion!$B$16,2020,2050),Report_Scenarios!$A$29:$A$35,1)+1,7))=INDEX(Report_Scenarios!$A$29:$A$35,MATCH(MEDIAN($B6-Conversion!$B$16,2020,2050),Report_Scenarios!$A$29:$A$35,1)),INDEX(Report_Scenarios!$E$29:$E$35,MATCH(MEDIAN($B6-Conversion!$B$16,2020,2050),Report_Scenarios!$A$29:$A$35,1)),INDEX(Report_Scenarios!$E$29:$E$35,MATCH(MEDIAN($B6-Conversion!$B$16,2020,2050),Report_Scenarios!$A$29:$A$35,1))+(INDEX(Report_Scenarios!$E$29:$E$35,MIN(MATCH(MEDIAN($B6-Conversion!$B$16,2020,2050),Report_Scenarios!$A$29:$A$35,1)+1,7))-INDEX(Report_Scenarios!$E$29:$E$35,MATCH(MEDIAN($B6-Conversion!$B$16,2020,2050),Report_Scenarios!$A$29:$A$35,1)))*(MEDIAN($B6-Conversion!$B$16,2020,2050)-INDEX(Report_Scenarios!$A$29:$A$35,MATCH(MEDIAN($B6-Conversion!$B$16,2020,2050),Report_Scenarios!$A$29:$A$35,1)))/(INDEX(Report_Scenarios!$A$29:$A$35,MIN(MATCH(MEDIAN($B6-Conversion!$B$16,2020,2050),Report_Scenarios!$A$29:$A$35,1)+1,7))-INDEX(Report_Scenarios!$A$29:$A$35,MATCH(MEDIAN($B6-Conversion!$B$16,2020,2050),Report_Scenarios!$A$29:$A$35,1)))))) | I6: =IF($D6="Conservative",IF(INDEX(Report_Scenarios!$A$7:$A$13,MIN(MATCH(MEDIAN($B6-Conversion!$B$16,2020,2050),Report_Scenarios!$A$7:$A$13,1)+1,7))=INDEX(Report_Scenarios!$A$7:$A$13,MATCH(MEDIAN($B6-Conversion!$B$16,2020,2050),Report_Scenarios!$A$7:$A$13,1)),INDEX(Report_Scenarios!$F$7:$F$13,MATCH(MEDIAN($B6-Conversion!$B$16,2020,2050),Report_Scenarios!$A$7:$A$13,1)),INDEX(Report_Scenarios!$F$7:$F$13,MATCH(MEDIAN($B6-Conversion!$B$16,2020,2050),Report_Scenarios!$A$7:$A$13,1))+(INDEX(Report_Scenarios!$F$7:$F$13,MIN(MATCH(MEDIAN($B6-Conversion!$B$16,2020,2050),Report_Scenarios!$A$7:$A$13,1)+1,7))-INDEX(Report_Scenarios!$F$7:$F$13,MATCH(MEDIAN($B6-Conversion!$B$16,2020,2050),Report_Scenarios!$A$7:$A$13,1)))*(MEDIAN($B6-Conversion!$B$16,2020,2050)-INDEX(Report_Scenarios!$A$7:$A$13,MATCH(MEDIAN($B6-Conversion!$B$16,2020,2050),Report_Scenarios!$A$7:$A$13,1)))/(INDEX(Report_Scenarios!$A$7:$A$13,MIN(MATCH(MEDIAN($B6-Conversion!$B$16,2020,2050),Report_Scenarios!$A$7:$A$13,1)+1,7))-INDEX(Report_Scenarios!$A$7:$A$13,MATCH(MEDIAN($B6-Conversion!$B$16,2020,2050),Report_Scenarios!$A$7:$A$13,1)))),IF($D6="Central",IF(INDEX(Report_Scenarios!$A$18:$A$24,MIN(MATCH(MEDIAN($B6-Conversion!$B$16,2020,2050),Report_Scenarios!$A$18:$A$24,1)+1,7))=INDEX(Report_Scenarios!$A$18:$A$24,MATCH(MEDIAN($B6-Conversion!$B$16,2020,2050),Report_Scenarios!$A$18:$A$24,1)),INDEX(Report_Scenarios!$F$18:$F$24,MATCH(MEDIAN($B6-Conversion!$B$16,2020,2050),Report_Scenarios!$A$18:$A$24,1)),INDEX(Report_Scenarios!$F$18:$F$24,MATCH(MEDIAN($B6-Conversion!$B$16,2020,2050),Report_Scenarios!$A$18:$A$24,1))+(INDEX(Report_Scenarios!$F$18:$F$24,MIN(MATCH(MEDIAN($B6-Conversion!$B$16,2020,2050),Report_Scenarios!$A$18:$A$24,1)+1,7))-INDEX(Report_Scenarios!$F$18:$F$24,MATCH(MEDIAN($B6-Conversion!$B$16,2020,2050),Report_Scenarios!$A$18:$A$24,1)))*(MEDIAN($B6-Conversion!$B$16,2020,2050)-INDEX(Report_Scenarios!$A$18:$A$24,MATCH(MEDIAN($B6-Conversion!$B$16,2020,2050),Report_Scenarios!$A$18:$A$24,1)))/(INDEX(Report_Scenarios!$A$18:$A$24,MIN(MATCH(MEDIAN($B6-Conversion!$B$16,2020,2050),Report_Scenarios!$A$18:$A$24,1)+1,7))-INDEX(Report_Scenarios!$A$18:$A$24,MATCH(MEDIAN($B6-Conversion!$B$16,2020,2050),Report_Scenarios!$A$18:$A$24,1)))),IF(INDEX(Report_Scenarios!$A$29:$A$35,MIN(MATCH(MEDIAN($B6-Conversion!$B$16,2020,2050),Report_Scenarios!$A$29:$A$35,1)+1,7))=INDEX(Report_Scenarios!$A$29:$A$35,MATCH(MEDIAN($B6-Conversion!$B$16,2020,2050),Report_Scenarios!$A$29:$A$35,1)),INDEX(Report_Scenarios!$F$29:$F$35,MATCH(MEDIAN($B6-Conversion!$B$16,2020,2050),Report_Scenarios!$A$29:$A$35,1)),INDEX(Report_Scenarios!$F$29:$F$35,MATCH(MEDIAN($B6-Conversion!$B$16,2020,2050),Report_Scenarios!$A$29:$A$35,1))+(INDEX(Report_Scenarios!$F$29:$F$35,MIN(MATCH(MEDIAN($B6-Conversion!$B$16,2020,2050),Report_Scenarios!$A$29:$A$35,1)+1,7))-INDEX(Report_Scenarios!$F$29:$F$35,MATCH(MEDIAN($B6-Conversion!$B$16,2020,2050),Report_Scenarios!$A$29:$A$35,1)))*(MEDIAN($B6-Conversion!$B$16,2020,2050)-INDEX(Report_Scenarios!$A$29:$A$35,MATCH(MEDIAN($B6-Conversion!$B$16,2020,2050),Report_Scenarios!$A$29:$A$35,1)))/(INDEX(Report_Scenarios!$A$29:$A$35,MIN(MATCH(MEDIAN($B6-Conversion!$B$16,2020,2050),Report_Scenarios!$A$29:$A$35,1)+1,7))-INDEX(Report_Scenarios!$A$29:$A$35,MATCH(MEDIAN($B6-Conversion!$B$16,2020,2050),Report_Scenarios!$A$29:$A$35,1)))))) | J6: =IF($D6="Conservative",IF(INDEX(Report_Scenarios!$A$7:$A$13,MIN(MATCH(MEDIAN($B6-Conversion!$B$16,2020,2050),Report_Scenarios!$A$7:$A$13,1)+1,7))=INDEX(Report_Scenarios!$A$7:$A$13,MATCH(MEDIAN($B6-Conversion!$B$16,2020,2050),Report_Scenarios!$A$7:$A$13,1)),INDEX(Report_Scenarios!$G$7:$G$13,MATCH(MEDIAN($B6-Conversion!$B$16,2020,2050),Report_Scenarios!$A$7:$A$13,1)),INDEX(Report_Scenarios!$G$7:$G$13,MATCH(MEDIAN($B6-Conversion!$B$16,2020,2050),Report_Scenarios!$A$7:$A$13,1))+(INDEX(Report_Scenarios!$G$7:$G$13,MIN(MATCH(MEDIAN($B6-Conversion!$B$16,2020,2050),Report_Scenarios!$A$7:$A$13,1)+1,7))-INDEX(Report_Scenarios!$G$7:$G$13,MATCH(MEDIAN($B6-Conversion!$B$16,2020,2050),Report_Scenarios!$A$7:$A$13,1)))*(MEDIAN($B6-Conversion!$B$16,2020,2050)-INDEX(Report_Scenarios!$A$7:$A$13,MATCH(MEDIAN($B6-Conversion!$B$16,2020,2050),Report_Scenarios!$A$7:$A$13,1)))/(INDEX(Report_Scenarios!$A$7:$A$13,MIN(MATCH(MEDIAN($B6-Conversion!$B$16,2020,2050),Report_Scenarios!$A$7:$A$13,1)+1,7))-INDEX(Report_Scenarios!$A$7:$A$13,MATCH(MEDIAN($B6-Conversion!$B$16,2020,2050),Report_Scenarios!$A$7:$A$13,1)))),IF($D6="Central",IF(INDEX(Report_Scenarios!$A$18:$A$24,MIN(MATCH(MEDIAN($B6-Conversion!$B$16,2020,2050),Report_Scenarios!$A$18:$A$24,1)+1,7))=INDEX(Report_Scenarios!$A$18:$A$24,MATCH(MEDIAN($B6-Conversion!$B$16,2020,2050),Report_Scenarios!$A$18:$A$24,1)),INDEX(Report_Scenarios!$G$18:$G$24,MATCH(MEDIAN($B6-Conversion!$B$16,2020,2050),Report_Scenarios!$A$18:$A$24,1)),INDEX(Report_Scenarios!$G$18:$G$24,MATCH(MEDIAN($B6-Conversion!$B$16,2020,2050),Report_Scenarios!$A$18:$A$24,1))+(INDEX(Report_Scenarios!$G$18:$G$24,MIN(MATCH(MEDIAN($B6-Conversion!$B$16,2020,2050),Report_Scenarios!$A$18:$A$24,1)+1,7))-INDEX(Report_Scenarios!$G$18:$G$24,MATCH(MEDIAN($B6-Conversion!$B$16,2020,2050),Report_Scenarios!$A$18:$A$24,1)))*(MEDIAN($B6-Conversion!$B$16,2020,2050)-INDEX(Report_Scenarios!$A$18:$A$24,MATCH(MEDIAN($B6-Conversion!$B$16,2020,2050),Report_Scenarios!$A$18:$A$24,1)))/(INDEX(Report_Scenarios!$A$18:$A$24,MIN(MATCH(MEDIAN($B6-Conversion!$B$16,2020,2050),Report_Scenarios!$A$18:$A$24,1)+1,7))-INDEX(Report_Scenarios!$A$18:$A$24,MATCH(MEDIAN($B6-Conversion!$B$16,2020,2050),Report_Scenarios!$A$18:$A$24,1)))),IF(INDEX(Report_Scenarios!$A$29:$A$35,MIN(MATCH(MEDIAN($B6-Conversion!$B$16,2020,2050),Report_Scenarios!$A$29:$A$35,1)+1,7))=INDEX(Report_Scenarios!$A$29:$A$35,MATCH(MEDIAN($B6-Conversion!$B$16,2020,2050),Report_Scenarios!$A$29:$A$35,1)),INDEX(Report_Scenarios!$G$29:$G$35,MATCH(MEDIAN($B6-Conversion!$B$16,2020,2050),Report_Scenarios!$A$29:$A$35,1)),INDEX(Report_Scenarios!$G$29:$G$35,MATCH(MEDIAN($B6-Conversion!$B$16,2020,2050),Report_Scenarios!$A$29:$A$35,1))+(INDEX(Report_Scenarios!$G$29:$G$35,MIN(MATCH(MEDIAN($B6-Conversion!$B$16,2020,2050),Report_Scenarios!$A$29:$A$35,1)+1,7))-INDEX(Report_Scenarios!$G$29:$G$35,MATCH(MEDIAN($B6-Conversion!$B$16,2020,2050),Report_Scenarios!$A$29:$A$35,1)))*(MEDIAN($B6-Conversion!$B$16,2020,2050)-INDEX(Report_Scenarios!$A$29:$A$35,MATCH(MEDIAN($B6-Conversion!$B$16,2020,2050),Report_Scenarios!$A$29:$A$35,1)))/(INDEX(Report_Scenarios!$A$29:$A$35,MIN(MATCH(MEDIAN($B6-Conversion!$B$16,2020,2050),Report_Scenarios!$A$29:$A$35,1)+1,7))-INDEX(Report_Scenarios!$A$29:$A$35,MATCH(MEDIAN($B6-Conversion!$B$16,2020,2050),Report_Scenarios!$A$29:$A$35,1)))))) | K6: =SUM(E6:J6) | L6: =IF(R6<>"",R6,IF($K6=0,0,E6/$K6)) | M6: =IF(S6<>"",S6,IF($K6=0,0,F6/$K6)) | N6: =IF(T6<>"",T6,IF($K6=0,0,G6/$K6)) | O6: =IF(U6<>"",U6,IF($K6=0,0,H6/$K6)) | P6: =IF(V6<>"",V6,IF($K6=0,0,I6/$K6)) | Q6: =IF(W6<>"",W6,IF($K6=0,0,J6/$K6))
